Workbook

Sheet Executive Dashboard
A1: SWISH 10-MIN DELIVERY — BANGALORE ZONE OPERATIONS DASHBOARD
A2: Executive control center — all figures update automatically from the underlying trackers.
A3: Report Date: | B3: =MAX('Daily Order Tracker'!$A$4:$A$93) -> 46282
A5: =COUNTIFS('Daily Order Tracker'!$A$4:$A$93,$B$3) -> 30 | C5: =COUNTIFS('Daily Order Tracker'!$A$4:$A$93,$B$3,'Daily Order Tracker'!$N$4:$N$93,"Delivered") -> 17 | E5: =COUNTIFS('Daily Order Tracker'!$A$4:$A$93,$B$3,'Daily Order Tracker'!$N$4:$N$93,"<>Delivered",'Daily Order Tracker'!$N$4:$N$93,"<>Cancelled") -> 8 | G5: =COUNTIF('Daily Order Tracker'!$N$4:$N$93,"Cancelled") -> 10 | I5: =SUMIFS('Daily Order Tracker'!$P$4:$P$93,'Daily Order Tracker'!$N$4:$N$93,"Delivered") -> 29595 | K5: =IFERROR(COUNTIFS('Daily Order Tracker'!$N$4:$N$93,"Delivered",'Daily Order Tracker'!$M$4:$M$93,"<=10")/COUNTIF('Daily Order Tracker'!$N$4:$N$93,"Delivered"),0) -> 0.25
A8: TODAY'S ORDERS | C8: COMPLETED DELIVERIES | E8: ACTIVE ORDERS | G8: CANCELLED ORDERS | I8: REVENUE (3-DAY) | K8: ON-TIME DELIVERY %
A10: =IFERROR(AVERAGEIFS('Daily Order Tracker'!$M$4:$M$93,'Daily Order Tracker'!$M$4:$M$93,"<>"),0) -> 11.875 | C10: =IFERROR(AVERAGEIFS('Daily Order Tracker'!$Q$4:$Q$93,'Daily Order Tracker'!$Q$4:$Q$93,"<>"),0) -> 5.96 | E10: =AVERAGE('Rider Performance Tracker'!$F$4:$F$23)/20 -> 0.18 | G10: =IFERROR(AVERAGEIFS('Daily Order Tracker'!$P$4:$P$93,'Daily Order Tracker'!$N$4:$N$93,"Delivered"),0) -> 411.04167 | I10: =COUNTA('Rider Performance Tracker'!$A$4:$A$23) -> 20 | K10: =COUNTIFS('Customer Complaints'!$F$4:$F$18,"<>Resolved") -> 8
A13: AVG DELIVERY TIME (min) | C13: AVG KITCHEN PREP TIME (min) | E13: RIDER UTILIZATION | G13: AVG ORDER VALUE | I13: ACTIVE RIDERS | K13: OPEN COMPLAINTS
A15: ZONE-WISE PERFORMANCE | G15: KITCHEN LOAD HEATMAP (orders by time block)
A16: Zone | B16: Orders | C16: Revenue (₹) | D16: Avg Delivery (min) | E16: Cancel Rate | G16: Kitchen | H16: 0-3 | I16: 4-7 | J16: 8-11 | K16: 12-15 | L16: 16-19
A17: ='Zone Performance'!A4 -> Koramangala | B17: ='Zone Performance'!B4 -> 9 | C17: ='Zone Performance'!C4 -> 3300 | D17: ='Zone Performance'!D4 -> 10.75 | E17: ='Zone Performance'!H4 -> 0 | G17: =Hourly_Helper!A2 -> Swish Kitchen - Koramangala | H17: =Hourly_Helper!AA2 -> 0 | I17: =Hourly_Helper!AB2 -> 0 | J17: =Hourly_Helper!AC2 -> 2 | K17: =Hourly_Helper!AD2 -> 2 | L17: =Hourly_Helper!AE2 -> 3
A18: ='Zone Performance'!A5 -> HSR Layout | B18: ='Zone Performance'!B5 -> 9 | C18: ='Zone Performance'!C5 -> 3262 | D18: ='Zone Performance'!D5 -> 11.857143 | E18: ='Zone Performance'!H5 -> 0.11111111 | G18: =Hourly_Helper!A3 -> Swish Kitchen - HSR Layout | H18: =Hourly_Helper!AA3 -> 0 | I18: =Hourly_Helper!AB3 -> 0 | J18: =Hourly_Helper!AC3 -> 3 | K18: =Hourly_Helper!AD3 -> 2 | L18: =Hourly_Helper!AE3 -> 2
A19: ='Zone Performance'!A6 -> Indiranagar | B19: ='Zone Performance'!B6 -> 9 | C19: ='Zone Performance'!C6 -> 3017 | D19: ='Zone Performance'!D6 -> 12.285714 | E19: ='Zone Performance'!H6 -> 0.22222222 | G19: =Hourly_Helper!A4 -> Swish Kitchen - Indiranagar | H19: =Hourly_Helper!AA4 -> 0 | I19: =Hourly_Helper!AB4 -> 0 | J19: =Hourly_Helper!AC4 -> 2 | K19: =Hourly_Helper!AD4 -> 1 | L19: =Hourly_Helper!AE4 -> 6
A20: ='Zone Performance'!A7 -> Whitefield | B20: ='Zone Performance'!B7 -> 9 | C20: ='Zone Performance'!C7 -> 2851 | D20: ='Zone Performance'!D7 -> 11.857143 | E20: ='Zone Performance'!H7 -> 0.22222222 | G20: =Hourly_Helper!A5 -> Swish Kitchen - Whitefield | H20: =Hourly_Helper!AA5 -> 0 | I20: =Hourly_Helper!AB5 -> 0 | J20: =Hourly_Helper!AC5 -> 4 | K20: =Hourly_Helper!AD5 -> 2 | L20: =Hourly_Helper!AE5 -> 2
A21: ='Zone Performance'!A8 -> Electronic City | B21: ='Zone Performance'!B8 -> 9 | C21: ='Zone Performance'!C8 -> 3082 | D21: ='Zone Performance'!D8 -> 13 | E21: ='Zone Performance'!H8 -> 0 | G21: =Hourly_Helper!A6 -> Swish Kitchen - Electronic City | H21: =Hourly_Helper!AA6 -> 0 | I21: =Hourly_Helper!AB6 -> 0 | J21: =Hourly_Helper!AC6 -> 4 | K21: =Hourly_Helper!AD6 -> 3 | L21: =Hourly_Helper!AE6 -> 1
A22: ='Zone Performance'!A9 -> Marathahalli | B22: ='Zone Performance'!B9 -> 9 | C22: ='Zone Performance'!C9 -> 2095 | D22: ='Zone Performance'!D9 -> 10.6 | E22: ='Zone Performance'!H9 -> 0.33333333 | G22: =Hourly_Helper!A7 -> Swish Kitchen - Marathahalli | H22: =Hourly_Helper!AA7 -> 0 | I22: =Hourly_Helper!AB7 -> 0 | J22: =Hourly_Helper!AC7 -> 3 | K22: =Hourly_Helper!AD7 -> 1 | L22: =Hourly_Helper!AE7 -> 4
A23: ='Zone Performance'!A10 -> JP Nagar | B23: ='Zone Performance'!B10 -> 9 | C23: ='Zone Performance'!C10 -> 2651 | D23: ='Zone Performance'!D10 -> 12.142857 | E23: ='Zone Performance'!H10 -> 0.11111111 | G23: =Hourly_Helper!A8 -> Swish Kitchen - JP Nagar | H23: =Hourly_Helper!AA8 -> 0 | I23: =Hourly_Helper!AB8 -> 0 | J23: =Hourly_Helper!AC8 -> 1 | K23: =Hourly_Helper!AD8 -> 4 | L23: =Hourly_Helper!AE8 -> 3
A24: ='Zone Performance'!A11 -> BTM Layout | B24: ='Zone Performance'!B11 -> 9 | C24: ='Zone Performance'!C11 -> 3148 | D24: ='Zone Performance'!D11 -> 13 | E24: ='Zone Performance'!H11 -> 0 | G24: =Hourly_Helper!A9 -> Swish Kitchen - BTM Layout | H24: =Hourly_Helper!AA9 -> 0 | I24: =Hourly_Helper!AB9 -> 0 | J24: =Hourly_Helper!AC9 -> 3 | K24: =Hourly_Helper!AD9 -> 1 | L24: =Hourly_Helper!AE9 -> 2
A25: ='Zone Performance'!A12 -> Bellandur | B25: ='Zone Performance'!B12 -> 9 | C25: ='Zone Performance'!C12 -> 3542 | D25: ='Zone Performance'!D12 -> 11.125 | E25: ='Zone Performance'!H12 -> 0 | G25: =Hourly_Helper!A10 -> Swish Kitchen - Bellandur | H25: =Hourly_Helper!AA10 -> 0 | I25: =Hourly_Helper!AB10 -> 0 | J25: =Hourly_Helper!AC10 -> 2 | K25: =Hourly_Helper!AD10 -> 1 | L25: =Hourly_Helper!AE10 -> 5
A26: ='Zone Performance'!A13 -> Sarjapur | B26: ='Zone Performance'!B13 -> 9 | C26: ='Zone Performance'!C13 -> 2647 | D26: ='Zone Performance'!D13 -> 11.714286 | E26: ='Zone Performance'!H13 -> 0.11111111 | G26: =Hourly_Helper!A11 -> Swish Kitchen - Sarjapur | H26: =Hourly_Helper!AA11 -> 0 | I26: =Hourly_Helper!AB11 -> 0 | J26: =Hourly_Helper!AC11 -> 2 | K26: =Hourly_Helper!AD11 -> 2 | L26: =Hourly_Helper!AE11 -> 3
A28: HOURLY ORDER TREND | G28: ZONE-WISE REVENUE

Sheet Daily Order Tracker
A1: DAILY ORDER TRACKER — Swish 10-Min Delivery (Bangalore Zone)
A2: Live order-level log. Grey helper columns (Q-S) power all analytics on other sheets — do not delete.
A3: Date | B3: Order ID | C3: Customer Name | D3: Phone | E3: Zone | F3: Kitchen | G3: Rider Assigned | H3: Order Time | I3: Preparation Start | J3: Preparation End | K3: Pickup Time | L3: Delivery Time | M3: Total Delivery Minutes | N3: Status | O3: Delay Reason | P3: Order Value | Q3: Prep Minutes (calc) | R3: Order Hour (calc) | S3: Delay Flag (calc)
A4: 46280 | B4: ORD1001 | C4: Ved Trivedi | D4: 9104332181 | E4: Koramangala | F4: Swish Kitchen - Koramangala | G4: R001 | H4: 0.72708333 | I4: 0.72708333 | J4: 0.72916667 | K4: 0.72916667 | L4: 0.73125 | M4: =IF(N4="Delivered",IFERROR((L4-H4)*1440,""),"") -> 6 | N4: Delivered | P4: 358 | Q4: =IF(AND(I4<>"",J4<>""),(J4-I4)*1440,"") -> 3 | R4: =IF(H4<>"",HOUR(H4),"") -> 17 | S4: =IF(AND(N4="Delivered",M4<>"",M4>10),"Y","N") -> N
A5: 46280 | B5: ORD1002 | C5: Aarav Shah | D5: 9838637940 | E5: HSR Layout | F5: Swish Kitchen - HSR Layout | G5: R004 | H5: 0.86875 | I5: 0.86875 | J5: 0.87430556 | K5: 0.875 | L5: 0.87777778 | M5: =IF(N5="Delivered",IFERROR((L5-H5)*1440,""),"") -> 13 | N5: Delivered | O5: Peak hour surge | P5: 404 | Q5: =IF(AND(I5<>"",J5<>""),(J5-I5)*1440,"") -> 8 | R5: =IF(H5<>"",HOUR(H5),"") -> 20 | S5: =IF(AND(N5="Delivered",M5<>"",M5>10),"Y","N") -> Y
A6: 46280 | B6: ORD1003 | C6: Arnav Sinha | D6: 9116155940 | E6: Indiranagar | F6: Swish Kitchen - Indiranagar | G6: R005 | H6: 0.81180556 | I6: 0.81180556 | J6: 0.81597222 | K6: 0.81597222 | L6: 0.82013889 | M6: =IF(N6="Delivered",IFERROR((L6-H6)*1440,""),"") -> 12 | N6: Delivered | O6: Address not found | P6: 420 | Q6: =IF(AND(I6<>"",J6<>""),(J6-I6)*1440,"") -> 6 | R6: =IF(H6<>"",HOUR(H6),"") -> 19 | S6: =IF(AND(N6="Delivered",M6<>"",M6>10),"Y","N") -> Y
A7: 46280 | B7: ORD1004 | C7: Reyan Dutta | D7: 9593103413 | E7: Whitefield | F7: Swish Kitchen - Whitefield | G7: R008 | H7: 0.87916667 | I7: 0.87986111 | J7: 0.88333333 | K7: 0.88402778 | L7: 0.88888889 | M7: =IF(N7="Delivered",IFERROR((L7-H7)*1440,""),"") -> 14 | N7: Delivered | O7: Heavy traffic | P7: 493 | Q7: =IF(AND(I7<>"",J7<>""),(J7-I7)*1440,"") -> 5 | R7: =IF(H7<>"",HOUR(H7),"") -> 21 | S7: =IF(AND(N7="Delivered",M7<>"",M7>10),"Y","N") -> Y
A8: 46280 | B8: ORD1005 | C8: Reyansh Jain | D8: 9419283276 | E8: Electronic City | F8: Swish Kitchen - Electronic City | G8: R009 | H8: 0.54097222 | I8: 0.54097222 | J8: 0.54652778 | K8: 0.54722222 | L8: 0.54861111 | M8: =IF(N8="Delivered",IFERROR((L8-H8)*1440,""),"") -> 11 | N8: Delivered | O8: Peak hour surge | P8: 354 | Q8: =IF(AND(I8<>"",J8<>""),(J8-I8)*1440,"") -> 8 | R8: =IF(H8<>"",HOUR(H8),"") -> 12 | S8: =IF(AND(N8="Delivered",M8<>"",M8>10),"Y","N") -> Y
A9: 46280 | B9: ORD1006 | C9: Arnav Sinha | D9: 9641395376 | E9: Marathahalli | F9: Swish Kitchen - Marathahalli | G9: R012 | H9: 0.77013889 | I9: 0.77013889 | J9: 0.77361111 | K9: 0.77361111 | L9: 0.77569444 | M9: =IF(N9="Delivered",IFERROR((L9-H9)*1440,""),"") -> 8 | N9: Delivered | P9: 389 | Q9: =IF(AND(I9<>"",J9<>""),(J9-I9)*1440,"") -> 5 | R9: =IF(H9<>"",HOUR(H9),"") -> 18 | S9: =IF(AND(N9="Delivered",M9<>"",M9>10),"Y","N") -> N
A10: 46280 | B10: ORD1007 | C10: Navya Desai | D10: 9965328710 | E10: JP Nagar | F10: Swish Kitchen - JP Nagar | G10: R013 | H10: 0.87986111 | I10: 0.87986111 | J10: 0.88541667 | K10: 0.88541667 | L10: 0.89027778 | M10: =IF(N10="Delivered",IFERROR((L10-H10)*1440,""),"") -> 15 | N10: Delivered | O10: High order volume | P10: 552 | Q10: =IF(AND(I10<>"",J10<>""),(J10-I10)*1440,"") -> 8 | R10: =IF(H10<>"",HOUR(H10),"") -> 21 | S10: =IF(AND(N10="Delivered",M10<>"",M10>10),"Y","N") -> Y
A11: 46280 | B11: ORD1008 | C11: Kian Fernandes | D11: 9978480184 | E11: BTM Layout | F11: Swish Kitchen - BTM Layout | G11: R016 | H11: 0.86180556 | I11: 0.8625 | J11: 0.86458333 | K11: 0.86527778 | L11: 0.86875 | M11: =IF(N11="Delivered",IFERROR((L11-H11)*1440,""),"") -> 10 | N11: Delivered | P11: 281 | Q11: =IF(AND(I11<>"",J11<>""),(J11-I11)*1440,"") -> 3 | R11: =IF(H11<>"",HOUR(H11),"") -> 20 | S11: =IF(AND(N11="Delivered",M11<>"",M11>10),"Y","N") -> N
A12: 46280 | B12: ORD1009 | C12: Ira Sharma | D12: 9482814893 | E12: Bellandur | F12: Swish Kitchen - Bellandur | G12: R017 | H12: 0.43263889 | I12: 0.43263889 | J12: 0.4375 | K12: 0.43888889 | L12: 0.44027778 | M12: =IF(N12="Delivered",IFERROR((L12-H12)*1440,""),"") -> 11 | N12: Delivered | O12: Rider unavailable at pickup | P12: 451 | Q12: =IF(AND(I12<>"",J12<>""),(J12-I12)*1440,"") -> 7 | R12: =IF(H12<>"",HOUR(H12),"") -> 10 | S12: =IF(AND(N12="Delivered",M12<>"",M12>10),"Y","N") -> Y
A13: 46280 | B13: ORD1010 | C13: Pihu Agarwal | D13: 9543039117 | E13: Sarjapur | F13: Swish Kitchen - Sarjapur | G13: R020 | H13: 0.87777778 | I13: 0.87777778 | J13: 0.88055556 | K13: 0.88194444 | L13: 0.88541667 | M13: =IF(N13="Delivered",IFERROR((L13-H13)*1440,""),"") -> 11 | N13: Delivered | O13: Peak hour surge | P13: 289 | Q13: =IF(AND(I13<>"",J13<>""),(J13-I13)*1440,"") -> 4 | R13: =IF(H13<>"",HOUR(H13),"") -> 21 | S13: =IF(AND(N13="Delivered",M13<>"",M13>10),"Y","N") -> Y
A14: 46280 | B14: ORD1011 | C14: Sanya Bhatia | D14: 9638346578 | E14: Koramangala | F14: Swish Kitchen - Koramangala | G14: R001 | H14: 0.62986111 | I14: 0.62986111 | J14: 0.63263889 | K14: 0.63263889 | L14: 0.63541667 | M14: =IF(N14="Delivered",IFERROR((L14-H14)*1440,""),"") -> 8 | N14: Delivered | P14: 141 | Q14: =IF(AND(I14<>"",J14<>""),(J14-I14)*1440,"") -> 4 | R14: =IF(H14<>"",HOUR(H14),"") -> 15 | S14: =IF(AND(N14="Delivered",M14<>"",M14>10),"Y","N") -> N
A15: 46280 | B15: ORD1012 | C15: Myra Kapoor | D15: 9930103105 | E15: HSR Layout | F15: Swish Kitchen - HSR Layout | G15: R004 | H15: 0.39722222 | I15: 0.39722222 | J15: 0.40069444 | K15: 0.40208333 | L15: 0.40555556 | M15: =IF(N15="Delivered",IFERROR((L15-H15)*1440,""),"") -> 12 | N15: Delivered | O15: Rider took wrong route | P15: 339 | Q15: =IF(AND(I15<>"",J15<>""),(J15-I15)*1440,"") -> 5 | R15: =IF(H15<>"",HOUR(H15),"") -> 9 | S15: =IF(AND(N15="Delivered",M15<>"",M15>10),"Y","N") -> Y
A16: 46280 | B16: ORD1013 | C16: Pihu Agarwal | D16: 9997376311 | E16: Indiranagar | F16: Swish Kitchen - Indiranagar | G16: R005 | H16: 0.76875 | I16: 0.76944444 | J16: 0.77361111 | K16: 0.77430556 | L16: 0.77777778 | M16: =IF(N16="Delivered",IFERROR((L16-H16)*1440,""),"") -> 13 | N16: Delivered | O16: Rider took wrong route | P16: 175 | Q16: =IF(AND(I16<>"",J16<>""),(J16-I16)*1440,"") -> 6 | R16: =IF(H16<>"",HOUR(H16),"") -> 18 | S16: =IF(AND(N16="Delivered",M16<>"",M16>10),"Y","N") -> Y
A17: 46280 | B17: ORD1014 | C17: Sara Khan | D17: 9065133387 | E17: Whitefield | F17: Swish Kitchen - Whitefield | G17: R008 | H17: 0.43541667 | I17: 0.43541667 | J17: 0.43888889 | K17: 0.43958333 | L17: 0.44166667 | M17: =IF(N17="Delivered",IFERROR((L17-H17)*1440,""),"") -> 9 | N17: Delivered | P17: 197 | Q17: =IF(AND(I17<>"",J17<>""),(J17-I17)*1440,"") -> 5 | R17: =IF(H17<>"",HOUR(H17),"") -> 10 | S17: =IF(AND(N17="Delivered",M17<>"",M17>10),"Y","N") -> N
A18: 46280 | B18: ORD1015 | C18: Kiara Vora | D18: 9810801326 | E18: Electronic City | F18: Swish Kitchen - Electronic City | G18: R009 | H18: 0.64583333 | I18: 0.64583333 | J18: 0.65208333 | K18: 0.65277778 | L18: 0.65416667 | M18: =IF(N18="Delivered",IFERROR((L18-H18)*1440,""),"") -> 12 | N18: Delivered | O18: High order volume | P18: 288 | Q18: =IF(AND(I18<>"",J18<>""),(J18-I18)*1440,"") -> 9 | R18: =IF(H18<>"",HOUR(H18),"") -> 15 | S18: =IF(AND(N18="Delivered",M18<>"",M18>10),"Y","N") -> Y
A19: 46280 | B19: ORD1016 | C19: Vivaan Chatterjee | D19: 9746872343 | E19: Marathahalli | F19: Swish Kitchen - Marathahalli | G19: R012 | H19: 0.35902778 | I19: 0.35902778 | J19: 0.36458333 | K19: 0.36527778 | L19: 0.36666667 | M19: =IF(N19="Delivered",IFERROR((L19-H19)*1440,""),"") -> 11 | N19: Delivered | O19: Address not found | P19: 171 | Q19: =IF(AND(I19<>"",J19<>""),(J19-I19)*1440,"") -> 8 | R19: =IF(H19<>"",HOUR(H19),"") -> 8 | S19: =IF(AND(N19="Delivered",M19<>"",M19>10),"Y","N") -> Y
A20: 46280 | B20: ORD1017 | C20: Pihu Agarwal | D20: 9820812191 | E20: JP Nagar | F20: Swish Kitchen - JP Nagar | G20: R013 | H20: 0.78819444 | I20: 0.78819444 | J20: 0.79236111 | K20: 0.79236111 | L20: 0.79652778 | M20: =IF(N20="Delivered",IFERROR((L20-H20)*1440,""),"") -> 12 | N20: Delivered | O20: Rider unavailable at pickup | P20: 372 | Q20: =IF(AND(I20<>"",J20<>""),(J20-I20)*1440,"") -> 6 | R20: =IF(H20<>"",HOUR(H20),"") -> 18 | S20: =IF(AND(N20="Delivered",M20<>"",M20>10),"Y","N") -> Y
A21: 46280 | B21: ORD1018 | C21: Sanya Bhatia | D21: 9169985435 | E21: BTM Layout | F21: Swish Kitchen - BTM Layout | G21: R016 | H21: 0.46944444 | I21: 0.47013889 | J21: 0.47291667 | K21: 0.47430556 | L21: 0.47916667 | M21: =IF(N21="Delivered",IFERROR((L21-H21)*1440,""),"") -> 14 | N21: Delivered | O21: Peak hour surge | P21: 427 | Q21: =IF(AND(I21<>"",J21<>""),(J21-I21)*1440,"") -> 4 | R21: =IF(H21<>"",HOUR(H21),"") -> 11 | S21: =IF(AND(N21="Delivered",M21<>"",M21>10),"Y","N") -> Y
A22: 46280 | B22: ORD1019 | C22: Pihu Agarwal | D22: 9107991183 | E22: Bellandur | F22: Swish Kitchen - Bellandur | G22: R017 | H22: 0.67777778 | I22: 0.67777778 | J22: 0.68125 | K22: 0.68125 | L22: 0.68333333 | M22: =IF(N22="Delivered",IFERROR((L22-H22)*1440,""),"") -> 8 | N22: Delivered | P22: 498 | Q22: =IF(AND(I22<>"",J22<>""),(J22-I22)*1440,"") -> 5 | R22: =IF(H22<>"",HOUR(H22),"") -> 16 | S22: =IF(AND(N22="Delivered",M22<>"",M22>10),"Y","N") -> N
A23: 46280 | B23: ORD1020 | C23: Dhruv Saxena | D23: 9849808412 | E23: Sarjapur | F23: Swish Kitchen - Sarjapur | G23: R020 | H23: 0.50486111 | I23: 0.50486111 | J23: 0.51041667 | K23: 0.51180556 | L23: 0.51388889 | M23: =IF(N23="Delivered",IFERROR((L23-H23)*1440,""),"") -> 13 | N23: Delivered | O23: Kitchen backlog | P23: 398 | Q23: =IF(AND(I23<>"",J23<>""),(J23-I23)*1440,"") -> 8 | R23: =IF(H23<>"",HOUR(H23),"") -> 12 | S23: =IF(AND(N23="Delivered",M23<>"",M23>10),"Y","N") -> Y
A24: 46280 | B24: ORD1021 | C24: Krish Choudhary | D24: 9534874016 | E24: Koramangala | F24: Swish Kitchen - Koramangala | G24: R001 | H24: 0.88680556 | I24: 0.88680556 | J24: 0.88888889 | K24: 0.88958333 | L24: 0.89166667 | M24: =IF(N24="Delivered",IFERROR((L24-H24)*1440,""),"") -> 7 | N24: Delivered | P24: 388 | Q24: =IF(AND(I24<>"",J24<>""),(J24-I24)*1440,"") -> 3 | R24: =IF(H24<>"",HOUR(H24),"") -> 21 | S24: =IF(AND(N24="Delivered",M24<>"",M24>10),"Y","N") -> N
A25: 46280 | B25: ORD1022 | C25: Dhruv Saxena | D25: 9868011280 | E25: HSR Layout | F25: Swish Kitchen - HSR Layout | G25: R004 | H25: 0.89097222 | I25: 0.89097222 | J25: 0.89513889 | K25: 0.89513889 | L25: 0.89652778 | M25: =IF(N25="Delivered",IFERROR((L25-H25)*1440,""),"") -> 8 | N25: Delivered | P25: 435 | Q25: =IF(AND(I25<>"",J25<>""),(J25-I25)*1440,"") -> 6 | R25: =IF(H25<>"",HOUR(H25),"") -> 21 | S25: =IF(AND(N25="Delivered",M25<>"",M25>10),"Y","N") -> N
A26: 46280 | B26: ORD1023 | C26: Pihu Agarwal | D26: 9053315869 | E26: Indiranagar | F26: Swish Kitchen - Indiranagar | G26: R005 | H26: 0.79791667 | M26: =IF(N26="Delivered",IFERROR((L26-H26)*1440,""),"") | N26: Cancelled | P26: 542 | Q26: =IF(AND(I26<>"",J26<>""),(J26-I26)*1440,"") | R26: =IF(H26<>"",HOUR(H26),"") -> 19 | S26: =IF(AND(N26="Delivered",M26<>"",M26>10),"Y","N") -> N
A27: 46280 | B27: ORD1024 | C27: Arnav Sinha | D27: 9634216073 | E27: Whitefield | F27: Swish Kitchen - Whitefield | G27: R008 | H27: 0.49444444 | I27: 0.49513889 | M27: =IF(N27="Delivered",IFERROR((L27-H27)*1440,""),"") | N27: Cancelled | P27: 348 | Q27: =IF(AND(I27<>"",J27<>""),(J27-I27)*1440,"") | R27: =IF(H27<>"",HOUR(H27),"") -> 11 | S27: =IF(AND(N27="Delivered",M27<>"",M27>10),"Y","N") -> N
A28: 46280 | B28: ORD1025 | C28: Arnav Sinha | D28: 9414586850 | E28: Electronic City | F28: Swish Kitchen - Electronic City | G28: R009 | H28: 0.41388889 | I28: 0.41458333 | J28: 0.41736111 | K28: 0.41875 | L28: 0.42152778 | M28: =IF(N28="Delivered",IFERROR((L28-H28)*1440,""),"") -> 11 | N28: Delivered | O28: High order volume | P28: 159 | Q28: =IF(AND(I28<>"",J28<>""),(J28-I28)*1440,"") -> 4 | R28: =IF(H28<>"",HOUR(H28),"") -> 9 | S28: =IF(AND(N28="Delivered",M28<>"",M28>10),"Y","N") -> Y
A29: 46280 | B29: ORD1026 | C29: Zara Ahmed | D29: 9569816934 | E29: Marathahalli | F29: Swish Kitchen - Marathahalli | G29: R012 | H29: 0.36458333 | I29: 0.36527778 | J29: 0.36736111 | K29: 0.36875 | L29: 0.37291667 | M29: =IF(N29="Delivered",IFERROR((L29-H29)*1440,""),"") -> 12 | N29: Delivered | O29: Rider unavailable at pickup | P29: 321 | Q29: =IF(AND(I29<>"",J29<>""),(J29-I29)*1440,"") -> 3 | R29: =IF(H29<>"",HOUR(H29),"") -> 8 | S29: =IF(AND(N29="Delivered",M29<>"",M29>10),"Y","N") -> Y
A30: 46280 | B30: ORD1027 | C30: Anaya Pillai | D30: 9595148465 | E30: JP Nagar | F30: Swish Kitchen - JP Nagar | G30: R013 | H30: 0.61388889 | I30: 0.61458333 | J30: 0.61944444 | K30: 0.61944444 | L30: 0.62152778 | M30: =IF(N30="Delivered",IFERROR((L30-H30)*1440,""),"") -> 11 | N30: Delivered | O30: High order volume | P30: 550 | Q30: =IF(AND(I30<>"",J30<>""),(J30-I30)*1440,"") -> 7 | R30: =IF(H30<>"",HOUR(H30),"") -> 14 | S30: =IF(AND(N30="Delivered",M30<>"",M30>10),"Y","N") -> Y
A31: 46280 | B31: ORD1028 | C31: Anaya Pillai | D31: 9299468044 | E31: BTM Layout | F31: Swish Kitchen - BTM Layout | G31: R016 | H31: 0.47708333 | I31: 0.47777778 | J31: 0.48194444 | K31: 0.48263889 | L31: 0.48611111 | M31: =IF(N31="Delivered",IFERROR((L31-H31)*1440,""),"") -> 13 | N31: Delivered | O31: Peak hour surge | P31: 338 | Q31: =IF(AND(I31<>"",J31<>""),(J31-I31)*1440,"") -> 6 | R31: =IF(H31<>"",HOUR(H31),"") -> 11 | S31: =IF(AND(N31="Delivered",M31<>"",M31>10),"Y","N") -> Y
A32: 46280 | B32: ORD1029 | C32: Reyan Dutta | D32: 9214895134 | E32: Bellandur | F32: Swish Kitchen - Bellandur | G32: R017 | H32: 0.49375 | I32: 0.49375 | J32: 0.49652778 | K32: 0.49652778 | L32: 0.49791667 | M32: =IF(N32="Delivered",IFERROR((L32-H32)*1440,""),"") -> 6 | N32: Delivered | P32: 370 | Q32: =IF(AND(I32<>"",J32<>""),(J32-I32)*1440,"") -> 4 | R32: =IF(H32<>"",HOUR(H32),"") -> 11 | S32: =IF(AND(N32="Delivered",M32<>"",M32>10),"Y","N") -> N
A33: 46280 | B33: ORD1030 | C33: Sanya Bhatia | D33: 9176936763 | E33: Sarjapur | F33: Swish Kitchen - Sarjapur | G33: R020 | H33: 0.44513889 | I33: 0.44513889 | J33: 0.45138889 | K33: 0.45138889 | L33: 0.45486111 | M33: =IF(N33="Delivered",IFERROR((L33-H33)*1440,""),"") -> 14 | N33: Delivered | O33: Rider took wrong route | P33: 344 | Q33: =IF(AND(I33<>"",J33<>""),(J33-I33)*1440,"") -> 9 | R33: =IF(H33<>"",HOUR(H33),"") -> 10 | S33: =IF(AND(N33="Delivered",M33<>"",M33>10),"Y","N") -> Y
A34: 46281 | B34: ORD1031 | C34: Aryan Bhatt | D34: 9708317278 | E34: HSR Layout | F34: Swish Kitchen - HSR Layout | G34: R003 | H34: 0.69305556 | I34: 0.69375 | J34: 0.7 | K34: 0.70069444 | L34: 0.70486111 | M34: =IF(N34="Delivered",IFERROR((L34-H34)*1440,""),"") -> 17 | N34: Delivered | O34: Address not found | P34: 636 | Q34: =IF(AND(I34<>"",J34<>""),(J34-I34)*1440,"") -> 9 | R34: =IF(H34<>"",HOUR(H34),"") -> 16 | S34: =IF(AND(N34="Delivered",M34<>"",M34>10),"Y","N") -> Y
A35: 46281 | B35: ORD1032 | C35: Dhruv Saxena | D35: 9277434873 | E35: Indiranagar | F35: Swish Kitchen - Indiranagar | G35: R006 | H35: 0.51944444 | I35: 0.51944444 | J35: 0.525 | K35: 0.52569444 | L35: 0.52777778 | M35: =IF(N35="Delivered",IFERROR((L35-H35)*1440,""),"") -> 12 | N35: Delivered | O35: Address not found | P35: 398 | Q35: =IF(AND(I35<>"",J35<>""),(J35-I35)*1440,"") -> 8 | R35: =IF(H35<>"",HOUR(H35),"") -> 12 | S35: =IF(AND(N35="Delivered",M35<>"",M35>10),"Y","N") -> Y
A36: 46281 | B36: ORD1033 | C36: Diya Mehta | D36: 9223623166 | E36: Whitefield | F36: Swish Kitchen - Whitefield | G36: R007 | H36: 0.56527778 | I36: 0.56597222 | J36: 0.57013889 | K36: 0.57013889 | L36: 0.57222222 | M36: =IF(N36="Delivered",IFERROR((L36-H36)*1440,""),"") -> 10 | N36: Delivered | P36: 550 | Q36: =IF(AND(I36<>"",J36<>""),(J36-I36)*1440,"") -> 6 | R36: =IF(H36<>"",HOUR(H36),"") -> 13 | S36: =IF(AND(N36="Delivered",M36<>"",M36>10),"Y","N") -> N
A37: 46281 | B37: ORD1034 | C37: Aarush Bali | D37: 9909670546 | E37: Electronic City | F37: Swish Kitchen - Electronic City | G37: R010 | H37: 0.91458333 | I37: 0.91527778 | J37: 0.92013889 | K37: 0.92152778 | L37: 0.92638889 | M37: =IF(N37="Delivered",IFERROR((L37-H37)*1440,""),"") -> 17 | N37: Delivered | O37: Heavy traffic | P37: 345 | Q37: =IF(AND(I37<>"",J37<>""),(J37-I37)*1440,"") -> 7 | R37: =IF(H37<>"",HOUR(H37),"") -> 21 | S37: =IF(AND(N37="Delivered",M37<>"",M37>10),"Y","N") -> Y
A38: 46281 | B38: ORD1035 | C38: Navya Desai | D38: 9706562729 | E38: Marathahalli | F38: Swish Kitchen - Marathahalli | G38: R011 | H38: 0.66736111 | M38: =IF(N38="Delivered",IFERROR((L38-H38)*1440,""),"") | N38: Cancelled | P38: 147 | Q38: =IF(AND(I38<>"",J38<>""),(J38-I38)*1440,"") | R38: =IF(H38<>"",HOUR(H38),"") -> 16 | S38: =IF(AND(N38="Delivered",M38<>"",M38>10),"Y","N") -> N
A39: 46281 | B39: ORD1036 | C39: Kiara Vora | D39: 9720465375 | E39: JP Nagar | F39: Swish Kitchen - JP Nagar | G39: R014 | H39: 0.575 | I39: 0.57569444 | J39: 0.57916667 | K39: 0.57986111 | L39: 0.58263889 | M39: =IF(N39="Delivered",IFERROR((L39-H39)*1440,""),"") -> 11 | N39: Delivered | O39: Rider took wrong route | P39: 203 | Q39: =IF(AND(I39<>"",J39<>""),(J39-I39)*1440,"") -> 5 | R39: =IF(H39<>"",HOUR(H39),"") -> 13 | S39: =IF(AND(N39="Delivered",M39<>"",M39>10),"Y","N") -> Y
A40: 46281 | B40: ORD1037 | C40: Tara Iyer | D40: 9053100330 | E40: BTM Layout | F40: Swish Kitchen - BTM Layout | G40: R015 | H40: 0.71458333 | I40: 0.71458333 | J40: 0.71736111 | K40: 0.71805556 | L40: 0.72291667 | M40: =IF(N40="Delivered",IFERROR((L40-H40)*1440,""),"") -> 12 | N40: Delivered | O40: Kitchen backlog | P40: 237 | Q40: =IF(AND(I40<>"",J40<>""),(J40-I40)*1440,"") -> 4 | R40: =IF(H40<>"",HOUR(H40),"") -> 17 | S40: =IF(AND(N40="Delivered",M40<>"",M40>10),"Y","N") -> Y
...

Sheet Hourly_Helper
A1: Kitchen | B1: 0 | C1: 1 | D1: 2 | E1: 3 | F1: 4 | G1: 5 | H1: 6 | I1: 7 | J1: 8 | K1: 9 | L1: 10 | M1: 11 | N1: 12 | O1: 13 | P1: 14 | Q1: 15 | R1: 16 | S1: 17 | T1: 18 | U1: 19 | V1: 20 | W1: 21 | X1: 22 | Y1: 23 | Z1: Peak Hour Load | AA1: Late Night 0-3 | AB1: Early Morn 4-7 | AC1: Morning 8-11 | AD1: Afternoon 12-15 | AE1: Evening 16-19 | AF1: Night 20-23
A2: Swish Kitchen - Koramangala | B2: =COUNTIFS('Daily Order Tracker'!$F$4:$F$93,$A2,'Daily Order Tracker'!$R$4:$R$93,0) -> 0 | C2: =COUNTIFS('Daily Order Tracker'!$F$4:$F$93,$A2,'Daily Order Tracker'!$R$4:$R$93,1) -> 0 | D2: =COUNTIFS('Daily Order Tracker'!$F$4:$F$93,$A2,'Daily Order Tracker'!$R$4:$R$93,2) -> 0 | E2: =COUNTIFS('Daily Order Tracker'!$F$4:$F$93,$A2,'Daily Order Tracker'!$R$4:$R$93,3) -> 0 | F2: =COUNTIFS('Daily Order Tracker'!$F$4:$F$93,$A2,'Daily Order Tracker'!$R$4:$R$93,4) -> 0 | G2: =COUNTIFS('Daily Order Tracker'!$F$4:$F$93,$A2,'Daily Order Tracker'!$R$4:$R$93,5) -> 0 | H2: =COUNTIFS('Daily Order Tracker'!$F$4:$F$93,$A2,'Daily Order Tracker'!$R$4:$R$93,6) -> 0 | I2: =COUNTIFS('Daily Order Tracker'!$F$4:$F$93,$A2,'Daily Order Tracker'!$R$4:$R$93,7) -> 0 | J2: =COUNTIFS('Daily Order Tracker'!$F$4:$F$93,$A2,'Daily Order Tracker'!$R$4:$R$93,8) -> 0 | K2: =COUNTIFS('Daily Order Tracker'!$F$4:$F$93,$A2,'Daily Order Tracker'!$R$4:$R$93,9) -> 1 | L2: =COUNTIFS('Daily Order Tracker'!$F$4:$F$93,$A2,'Daily Order Tracker'!$R$4:$R$93,10) -> 0 | M2: =COUNTIFS('Daily Order Tracker'!$F$4:$F$93,$A2,'Daily Order Tracker'!$R$4:$R$93,11) -> 1 | N2: =COUNTIFS('Daily Order Tracker'!$F$4:$F$93,$A2,'Daily Order Tracker'!$R$4:$R$93,12) -> 0 | O2: =COUNTIFS('Daily Order Tracker'!$F$4:$F$93,$A2,'Daily Order Tracker'!$R$4:$R$93,13) -> 0 | P2: =COUNTIFS('Daily Order Tracker'!$F$4:$F$93,$A2,'Daily Order Tracker'!$R$4:$R$93,14) -> 0 | Q2: =COUNTIFS('Daily Order Tracker'!$F$4:$F$93,$A2,'Daily Order Tracker'!$R$4:$R$93,15) -> 2 | R2: =COUNTIFS('Daily Order Tracker'!$F$4:$F$93,$A2,'Daily Order Tracker'!$R$4:$R$93,16) -> 0 | S2: =COUNTIFS('Daily Order Tracker'!$F$4:$F$93,$A2,'Daily Order Tracker'!$R$4:$R$93,17) -> 2 | T2: =COUNTIFS('Daily Order Tracker'!$F$4:$F$93,$A2,'Daily Order Tracker'!$R$4:$R$93,18) -> 1 | U2: =COUNTIFS('Daily Order Tracker'!$F$4:$F$93,$A2,'Daily Order Tracker'!$R$4:$R$93,19) -> 0 | V2: =COUNTIFS('Daily Order Tracker'!$F$4:$F$93,$A2,'Daily Order Tracker'!$R$4:$R$93,20) -> 0 | W2: =COUNTIFS('Daily Order Tracker'!$F$4:$F$93,$A2,'Daily Order Tracker'!$R$4:$R$93,21) -> 2 | X2: =COUNTIFS('Daily Order Tracker'!$F$4:$F$93,$A2,'Daily Order Tracker'!$R$4:$R$93,22) -> 0 | Y2: =COUNTIFS('Daily Order Tracker'!$F$4:$F$93,$A2,'Daily Order Tracker'!$R$4:$R$93,23) -> 0 | Z2: =MAX(B2:Y2) -> 2 | AA2: =SUM(B2:E2) -> 0 | AB2: =SUM(F2:I2) -> 0 | AC2: =SUM(J2:M2) -> 2 | AD2: =SUM(N2:Q2) -> 2 | AE2: =SUM(R2:U2) -> 3 | AF2: =SUM(V2:Y2) -> 2
A3: Swish Kitchen - HSR Layout | B3: =COUNTIFS('Daily Order Tracker'!$F$4:$F$93,$A3,'Daily Order Tracker'!$R$4:$R$93,0) -> 0 | C3: =COUNTIFS('Daily Order Tracker'!$F$4:$F$93,$A3,'Daily Order Tracker'!$R$4:$R$93,1) -> 0 | D3: =COUNTIFS('Daily Order Tracker'!$F$4:$F$93,$A3,'Daily Order Tracker'!$R$4:$R$93,2) -> 0 | E3: =COUNTIFS('Daily Order Tracker'!$F$4:$F$93,$A3,'Daily Order Tracker'!$R$4:$R$93,3) -> 0 | F3: =COUNTIFS('Daily Order Tracker'!$F$4:$F$93,$A3,'Daily Order Tracker'!$R$4:$R$93,4) -> 0 | G3: =COUNTIFS('Daily Order Tracker'!$F$4:$F$93,$A3,'Daily Order Tracker'!$R$4:$R$93,5) -> 0 | H3: =COUNTIFS('Daily Order Tracker'!$F$4:$F$93,$A3,'Daily Order Tracker'!$R$4:$R$93,6) -> 0 | I3: =COUNTIFS('Daily Order Tracker'!$F$4:$F$93,$A3,'Daily Order Tracker'!$R$4:$R$93,7) -> 0 | J3: =COUNTIFS('Daily Order Tracker'!$F$4:$F$93,$A3,'Daily Order Tracker'!$R$4:$R$93,8) -> 2 | K3: =COUNTIFS('Daily Order Tracker'!$F$4:$F$93,$A3,'Daily Order Tracker'!$R$4:$R$93,9) -> 1 | L3: =COUNTIFS('Daily Order Tracker'!$F$4:$F$93,$A3,'Daily Order Tracker'!$R$4:$R$93,10) -> 0 | M3: =COUNTIFS('Daily Order Tracker'!$F$4:$F$93,$A3,'Daily Order Tracker'!$R$4:$R$93,11) -> 0 | N3: =COUNTIFS('Daily Order Tracker'!$F$4:$F$93,$A3,'Daily Order Tracker'!$R$4:$R$93,12) -> 0 | O3: =COUNTIFS('Daily Order Tracker'!$F$4:$F$93,$A3,'Daily Order Tracker'!$R$4:$R$93,13) -> 0 | P3: =COUNTIFS('Daily Order Tracker'!$F$4:$F$93,$A3,'Daily Order Tracker'!$R$4:$R$93,14) -> 0 | Q3: =COUNTIFS('Daily Order Tracker'!$F$4:$F$93,$A3,'Daily Order Tracker'!$R$4:$R$93,15) -> 2 | R3: =COUNTIFS('Daily Order Tracker'!$F$4:$F$93,$A3,'Daily Order Tracker'!$R$4:$R$93,16) -> 1 | S3: =COUNTIFS('Daily Order Tracker'!$F$4:$F$93,$A3,'Daily Order Tracker'!$R$4:$R$93,17) -> 0 | T3: =COUNTIFS('Daily Order Tracker'!$F$4:$F$93,$A3,'Daily Order Tracker'!$R$4:$R$93,18) -> 0 | U3: =COUNTIFS('Daily Order Tracker'!$F$4:$F$93,$A3,'Daily Order Tracker'!$R$4:$R$93,19) -> 1 | V3: =COUNTIFS('Daily Order Tracker'!$F$4:$F$93,$A3,'Daily Order Tracker'!$R$4:$R$93,20) -> 1 | W3: =COUNTIFS('Daily Order Tracker'!$F$4:$F$93,$A3,'Daily Order Tracker'!$R$4:$R$93,21) -> 1 | X3: =COUNTIFS('Daily Order Tracker'!$F$4:$F$93,$A3,'Daily Order Tracker'!$R$4:$R$93,22) -> 0 | Y3: =COUNTIFS('Daily Order Tracker'!$F$4:$F$93,$A3,'Daily Order Tracker'!$R$4:$R$93,23) -> 0 | Z3: =MAX(B3:Y3) -> 2 | AA3: =SUM(B3:E3) -> 0 | AB3: =SUM(F3:I3) -> 0 | AC3: =SUM(J3:M3) -> 3 | AD3: =SUM(N3:Q3) -> 2 | AE3: =SUM(R3:U3) -> 2 | AF3: =SUM(V3:Y3) -> 2
A4: Swish Kitchen - Indiranagar | B4: =COUNTIFS('Daily Order Tracker'!$F$4:$F$93,$A4,'Daily Order Tracker'!$R$4:$R$93,0) -> 0 | C4: =COUNTIFS('Daily Order Tracker'!$F$4:$F$93,$A4,'Daily Order Tracker'!$R$4:$R$93,1) -> 0 | D4: =COUNTIFS('Daily Order Tracker'!$F$4:$F$93,$A4,'Daily Order Tracker'!$R$4:$R$93,2) -> 0 | E4: =COUNTIFS('Daily Order Tracker'!$F$4:$F$93,$A4,'Daily Order Tracker'!$R$4:$R$93,3) -> 0 | F4: =COUNTIFS('Daily Order Tracker'!$F$4:$F$93,$A4,'Daily Order Tracker'!$R$4:$R$93,4) -> 0 | G4: =COUNTIFS('Daily Order Tracker'!$F$4:$F$93,$A4,'Daily Order Tracker'!$R$4:$R$93,5) -> 0 | H4: =COUNTIFS('Daily Order Tracker'!$F$4:$F$93,$A4,'Daily Order Tracker'!$R$4:$R$93,6) -> 0 | I4: =COUNTIFS('Daily Order Tracker'!$F$4:$F$93,$A4,'Daily Order Tracker'!$R$4:$R$93,7) -> 0 | J4: =COUNTIFS('Daily Order Tracker'!$F$4:$F$93,$A4,'Daily Order Tracker'!$R$4:$R$93,8) -> 1 | K4: =COUNTIFS('Daily Order Tracker'!$F$4:$F$93,$A4,'Daily Order Tracker'!$R$4:$R$93,9) -> 0 | L4: =COUNTIFS('Daily Order Tracker'!$F$4:$F$93,$A4,'Daily Order Tracker'!$R$4:$R$93,10) -> 1 | M4: =COUNTIFS('Daily Order Tracker'!$F$4:$F$93,$A4,'Daily Order Tracker'!$R$4:$R$93,11) -> 0 | N4: =COUNTIFS('Daily Order Tracker'!$F$4:$F$93,$A4,'Daily Order Tracker'!$R$4:$R$93,12) -> 1 | O4: =COUNTIFS('Daily Order Tracker'!$F$4:$F$93,$A4,'Daily Order Tracker'!$R$4:$R$93,13) -> 0 | P4: =COUNTIFS('Daily Order Tracker'!$F$4:$F$93,$A4,'Daily Order Tracker'!$R$4:$R$93,14) -> 0 | Q4: =COUNTIFS('Daily Order Tracker'!$F$4:$F$93,$A4,'Daily Order Tracker'!$R$4:$R$93,15) -> 0 | R4: =COUNTIFS('Daily Order Tracker'!$F$4:$F$93,$A4,'Daily Order Tracker'!$R$4:$R$93,16) -> 0 | S4: =COUNTIFS('Daily Order Tracker'!$F$4:$F$93,$A4,'Daily Order Tracker'!$R$4:$R$93,17) -> 0 | T4: =COUNTIFS('Daily Order Tracker'!$F$4:$F$93,$A4,'Daily Order Tracker'!$R$4:$R$93,18) -> 3 | U4: =COUNTIFS('Daily Order Tracker'!$F$4:$F$93,$A4,'Daily Order Tracker'!$R$4:$R$93,19) -> 3 | V4: =COUNTIFS('Daily Order Tracker'!$F$4:$F$93,$A4,'Daily Order Tracker'!$R$4:$R$93,20) -> 0 | W4: =COUNTIFS('Daily Order Tracker'!$F$4:$F$93,$A4,'Daily Order Tracker'!$R$4:$R$93,21) -> 0 | X4: =COUNTIFS('Daily Order Tracker'!$F$4:$F$93,$A4,'Daily Order Tracker'!$R$4:$R$93,22) -> 0 | Y4: =COUNTIFS('Daily Order Tracker'!$F$4:$F$93,$A4,'Daily Order Tracker'!$R$4:$R$93,23) -> 0 | Z4: =MAX(B4:Y4) -> 3 | AA4: =SUM(B4:E4) -> 0 | AB4: =SUM(F4:I4) -> 0 | AC4: =SUM(J4:M4) -> 2 | AD4: =SUM(N4:Q4) -> 1 | AE4: =SUM(R4:U4) -> 6 | AF4: =SUM(V4:Y4) -> 0
A5: Swish Kitchen - Whitefield | B5: =COUNTIFS('Daily Order Tracker'!$F$4:$F$93,$A5,'Daily Order Tracker'!$R$4:$R$93,0) -> 0 | C5: =COUNTIFS('Daily Order Tracker'!$F$4:$F$93,$A5,'Daily Order Tracker'!$R$4:$R$93,1) -> 0 | D5: =COUNTIFS('Daily Order Tracker'!$F$4:$F$93,$A5,'Daily Order Tracker'!$R$4:$R$93,2) -> 0 | E5: =COUNTIFS('Daily Order Tracker'!$F$4:$F$93,$A5,'Daily Order Tracker'!$R$4:$R$93,3) -> 0 | F5: =COUNTIFS('Daily Order Tracker'!$F$4:$F$93,$A5,'Daily Order Tracker'!$R$4:$R$93,4) -> 0 | G5: =COUNTIFS('Daily Order Tracker'!$F$4:$F$93,$A5,'Daily Order Tracker'!$R$4:$R$93,5) -> 0 | H5: =COUNTIFS('Daily Order Tracker'!$F$4:$F$93,$A5,'Daily Order Tracker'!$R$4:$R$93,6) -> 0 | I5: =COUNTIFS('Daily Order Tracker'!$F$4:$F$93,$A5,'Daily Order Tracker'!$R$4:$R$93,7) -> 0 | J5: =COUNTIFS('Daily Order Tracker'!$F$4:$F$93,$A5,'Daily Order Tracker'!$R$4:$R$93,8) -> 0 | K5: =COUNTIFS('Daily Order Tracker'!$F$4:$F$93,$A5,'Daily Order Tracker'!$R$4:$R$93,9) -> 1 | L5: =COUNTIFS('Daily Order Tracker'!$F$4:$F$93,$A5,'Daily Order Tracker'!$R$4:$R$93,10) -> 2 | M5: =COUNTIFS('Daily Order Tracker'!$F$4:$F$93,$A5,'Daily Order Tracker'!$R$4:$R$93,11) -> 1 | N5: =COUNTIFS('Daily Order Tracker'!$F$4:$F$93,$A5,'Daily Order Tracker'!$R$4:$R$93,12) -> 0 | O5: =COUNTIFS('Daily Order Tracker'!$F$4:$F$93,$A5,'Daily Order Tracker'!$R$4:$R$93,13) -> 1 | P5: =COUNTIFS('Daily Order Tracker'!$F$4:$F$93,$A5,'Daily Order Tracker'!$R$4:$R$93,14) -> 0 | Q5: =COUNTIFS('Daily Order Tracker'!$F$4:$F$93,$A5,'Daily Order Tracker'!$R$4:$R$93,15) -> 1 | R5: =COUNTIFS('Daily Order Tracker'!$F$4:$F$93,$A5,'Daily Order Tracker'!$R$4:$R$93,16) -> 1 | S5: =COUNTIFS('Daily Order Tracker'!$F$4:$F$93,$A5,'Daily Order Tracker'!$R$4:$R$93,17) -> 0 | T5: =COUNTIFS('Daily Order Tracker'!$F$4:$F$93,$A5,'Daily Order Tracker'!$R$4:$R$93,18) -> 1 | U5: =COUNTIFS('Daily Order Tracker'!$F$4:$F$93,$A5,'Daily Order Tracker'!$R$4:$R$93,19) -> 0 | V5: =COUNTIFS('Daily Order Tracker'!$F$4:$F$93,$A5,'Daily Order Tracker'!$R$4:$R$93,20) -> 0 | W5: =COUNTIFS('Daily Order Tracker'!$F$4:$F$93,$A5,'Daily Order Tracker'!$R$4:$R$93,21) -> 1 | X5: =COUNTIFS('Daily Order Tracker'!$F$4:$F$93,$A5,'Daily Order Tracker'!$R$4:$R$93,22) -> 0 | Y5: =COUNTIFS('Daily Order Tracker'!$F$4:$F$93,$A5,'Daily Order Tracker'!$R$4:$R$93,23) -> 0 | Z5: =MAX(B5:Y5) -> 2 | AA5: =SUM(B5:E5) -> 0 | AB5: =SUM(F5:I5) -> 0 | AC5: =SUM(J5:M5) -> 4 | AD5: =SUM(N5:Q5) -> 2 | AE5: =SUM(R5:U5) -> 2 | AF5: =SUM(V5:Y5) -> 1
A6: Swish Kitchen - Electronic City | B6: =COUNTIFS('Daily Order Tracker'!$F$4:$F$93,$A6,'Daily Order Tracker'!$R$4:$R$93,0) -> 0 | C6: =COUNTIFS('Daily Order Tracker'!$F$4:$F$93,$A6,'Daily Order Tracker'!$R$4:$R$93,1) -> 0 | D6: =COUNTIFS('Daily Order Tracker'!$F$4:$F$93,$A6,'Daily Order Tracker'!$R$4:$R$93,2) -> 0 | E6: =COUNTIFS('Daily Order Tracker'!$F$4:$F$93,$A6,'Daily Order Tracker'!$R$4:$R$93,3) -> 0 | F6: =COUNTIFS('Daily Order Tracker'!$F$4:$F$93,$A6,'Daily Order Tracker'!$R$4:$R$93,4) -> 0 | G6: =COUNTIFS('Daily Order Tracker'!$F$4:$F$93,$A6,'Daily Order Tracker'!$R$4:$R$93,5) -> 0 | H6: =COUNTIFS('Daily Order Tracker'!$F$4:$F$93,$A6,'Daily Order Tracker'!$R$4:$R$93,6) -> 0 | I6: =COUNTIFS('Daily Order Tracker'!$F$4:$F$93,$A6,'Daily Order Tracker'!$R$4:$R$93,7) -> 0 | J6: =COUNTIFS('Daily Order Tracker'!$F$4:$F$93,$A6,'Daily Order Tracker'!$R$4:$R$93,8) -> 0 | K6: =COUNTIFS('Daily Order Tracker'!$F$4:$F$93,$A6,'Daily Order Tracker'!$R$4:$R$93,9) -> 2 | L6: =COUNTIFS('Daily Order Tracker'!$F$4:$F$93,$A6,'Daily Order Tracker'!$R$4:$R$93,10) -> 1 | M6: =COUNTIFS('Daily Order Tracker'!$F$4:$F$93,$A6,'Daily Order Tracker'!$R$4:$R$93,11) -> 1 | N6: =COUNTIFS('Daily Order Tracker'!$F$4:$F$93,$A6,'Daily Order Tracker'!$R$4:$R$93,12) -> 1 | O6: =COUNTIFS('Daily Order Tracker'!$F$4:$F$93,$A6,'Daily Order Tracker'!$R$4:$R$93,13) -> 1 | P6: =COUNTIFS('Daily Order Tracker'!$F$4:$F$93,$A6,'Daily Order Tracker'!$R$4:$R$93,14) -> 0 | Q6: =COUNTIFS('Daily Order Tracker'!$F$4:$F$93,$A6,'Daily Order Tracker'!$R$4:$R$93,15) -> 1 | R6: =COUNTIFS('Daily Order Tracker'!$F$4:$F$93,$A6,'Daily Order Tracker'!$R$4:$R$93,16) -> 1 | S6: =COUNTIFS('Daily Order Tracker'!$F$4:$F$93,$A6,'Daily Order Tracker'!$R$4:$R$93,17) -> 0 | T6: =COUNTIFS('Daily Order Tracker'!$F$4:$F$93,$A6,'Daily Order Tracker'!$R$4:$R$93,18) -> 0 | U6: =COUNTIFS('Daily Order Tracker'!$F$4:$F$93,$A6,'Daily Order Tracker'!$R$4:$R$93,19) -> 0 | V6: =COUNTIFS('Daily Order Tracker'!$F$4:$F$93,$A6,'Daily Order Tracker'!$R$4:$R$93,20) -> 0 | W6: =COUNTIFS('Daily Order Tracker'!$F$4:$F$93,$A6,'Daily Order Tracker'!$R$4:$R$93,21) -> 1 | X6: =COUNTIFS('Daily Order Tracker'!$F$4:$F$93,$A6,'Daily Order Tracker'!$R$4:$R$93,22) -> 0 | Y6: =COUNTIFS('Daily Order Tracker'!$F$4:$F$93,$A6,'Daily Order Tracker'!$R$4:$R$93,23) -> 0 | Z6: =MAX(B6:Y6) -> 2 | AA6: =SUM(B6:E6) -> 0 | AB6: =SUM(F6:I6) -> 0 | AC6: =SUM(J6:M6) -> 4 | AD6: =SUM(N6:Q6) -> 3 | AE6: =SUM(R6:U6) -> 1 | AF6: =SUM(V6:Y6) -> 1
A7: Swish Kitchen - Marathahalli | B7: =COUNTIFS('Daily Order Tracker'!$F$4:$F$93,$A7,'Daily Order Tracker'!$R$4:$R$93,0) -> 0 | C7: =COUNTIFS('Daily Order Tracker'!$F$4:$F$93,$A7,'Daily Order Tracker'!$R$4:$R$93,1) -> 0 | D7: =COUNTIFS('Daily Order Tracker'!$F$4:$F$93,$A7,'Daily Order Tracker'!$R$4:$R$93,2) -> 0 | E7: =COUNTIFS('Daily Order Tracker'!$F$4:$F$93,$A7,'Daily Order Tracker'!$R$4:$R$93,3) -> 0 | F7: =COUNTIFS('Daily Order Tracker'!$F$4:$F$93,$A7,'Daily Order Tracker'!$R$4:$R$93,4) -> 0 | G7: =COUNTIFS('Daily Order Tracker'!$F$4:$F$93,$A7,'Daily Order Tracker'!$R$4:$R$93,5) -> 0 | H7: =COUNTIFS('Daily Order Tracker'!$F$4:$F$93,$A7,'Daily Order Tracker'!$R$4:$R$93,6) -> 0 | I7: =COUNTIFS('Daily Order Tracker'!$F$4:$F$93,$A7,'Daily Order Tracker'!$R$4:$R$93,7) -> 0 | J7: =COUNTIFS('Daily Order Tracker'!$F$4:$F$93,$A7,'Daily Order Tracker'!$R$4:$R$93,8) -> 3 | K7: =COUNTIFS('Daily Order Tracker'!$F$4:$F$93,$A7,'Daily Order Tracker'!$R$4:$R$93,9) -> 0 | L7: =COUNTIFS('Daily Order Tracker'!$F$4:$F$93,$A7,'Daily Order Tracker'!$R$4:$R$93,10) -> 0 | M7: =COUNTIFS('Daily Order Tracker'!$F$4:$F$93,$A7,'Daily Order Tracker'!$R$4:$R$93,11) -> 0 | N7: =COUNTIFS('Daily Order Tracker'!$F$4:$F$93,$A7,'Daily Order Tracker'!$R$4:$R$93,12) -> 0 | O7: =COUNTIFS('Daily Order Tracker'!$F$4:$F$93,$A7,'Daily Order Tracker'!$R$4:$R$93,13) -> 0 | P7: =COUNTIFS('Daily Order Tracker'!$F$4:$F$93,$A7,'Daily Order Tracker'!$R$4:$R$93,14) -> 1 | Q7: =COUNTIFS('Daily Order Tracker'!$F$4:$F$93,$A7,'Daily Order Tracker'!$R$4:$R$93,15) -> 0 | R7: =COUNTIFS('Daily Order Tracker'!$F$4:$F$93,$A7,'Daily Order Tracker'!$R$4:$R$93,16) -> 2 | S7: =COUNTIFS('Daily Order Tracker'!$F$4:$F$93,$A7,'Daily Order Tracker'!$R$4:$R$93,17) -> 1 | T7: =COUNTIFS('Daily Order Tracker'!$F$4:$F$93,$A7,'Daily Order Tracker'!$R$4:$R$93,18) -> 1 | U7: =COUNTIFS('Daily Order Tracker'!$F$4:$F$93,$A7,'Daily Order Tracker'!$R$4:$R$93,19) -> 0 | V7: =COUNTIFS('Daily Order Tracker'!$F$4:$F$93,$A7,'Daily Order Tracker'!$R$4:$R$93,20) -> 0 | W7: =COUNTIFS('Daily Order Tracker'!$F$4:$F$93,$A7,'Daily Order Tracker'!$R$4:$R$93,21) -> 1 | X7: =COUNTIFS('Daily Order Tracker'!$F$4:$F$93,$A7,'Daily Order Tracker'!$R$4:$R$93,22) -> 0 | Y7: =COUNTIFS('Daily Order Tracker'!$F$4:$F$93,$A7,'Daily Order Tracker'!$R$4:$R$93,23) -> 0 | Z7: =MAX(B7:Y7) -> 3 | AA7: =SUM(B7:E7) -> 0 | AB7: =SUM(F7:I7) -> 0 | AC7: =SUM(J7:M7) -> 3 | AD7: =SUM(N7:Q7) -> 1 | AE7: =SUM(R7:U7) -> 4 | AF7: =SUM(V7:Y7) -> 1
A8: Swish Kitchen - JP Nagar | B8: =COUNTIFS('Daily Order Tracker'!$F$4:$F$93,$A8,'Daily Order Tracker'!$R$4:$R$93,0) -> 0 | C8: =COUNTIFS('Daily Order Tracker'!$F$4:$F$93,$A8,'Daily Order Tracker'!$R$4:$R$93,1) -> 0 | D8: =COUNTIFS('Daily Order Tracker'!$F$4:$F$93,$A8,'Daily Order Tracker'!$R$4:$R$93,2) -> 0 | E8: =COUNTIFS('Daily Order Tracker'!$F$4:$F$93,$A8,'Daily Order Tracker'!$R$4:$R$93,3) -> 0 | F8: =COUNTIFS('Daily Order Tracker'!$F$4:$F$93,$A8,'Daily Order Tracker'!$R$4:$R$93,4) -> 0 | G8: =COUNTIFS('Daily Order Tracker'!$F$4:$F$93,$A8,'Daily Order Tracker'!$R$4:$R$93,5) -> 0 | H8: =COUNTIFS('Daily Order Tracker'!$F$4:$F$93,$A8,'Daily Order Tracker'!$R$4:$R$93,6) -> 0 | I8: =COUNTIFS('Daily Order Tracker'!$F$4:$F$93,$A8,'Daily Order Tracker'!$R$4:$R$93,7) -> 0 | J8: =COUNTIFS('Daily Order Tracker'!$F$4:$F$93,$A8,'Daily Order Tracker'!$R$4:$R$93,8) -> 0 | K8: =COUNTIFS('Daily Order Tracker'!$F$4:$F$93,$A8,'Daily Order Tracker'!$R$4:$R$93,9) -> 1 | L8: =COUNTIFS('Daily Order Tracker'!$F$4:$F$93,$A8,'Daily Order Tracker'!$R$4:$R$93,10) -> 0 | M8: =COUNTIFS('Daily Order Tracker'!$F$4:$F$93,$A8,'Daily Order Tracker'!$R$4:$R$93,11) -> 0 | N8: =COUNTIFS('Daily Order Tracker'!$F$4:$F$93,$A8,'Daily Order Tracker'!$R$4:$R$93,12) -> 0 | O8: =COUNTIFS('Daily Order Tracker'!$F$4:$F$93,$A8,'Daily Order Tracker'!$R$4:$R$93,13) -> 1 | P8: =COUNTIFS('Daily Order Tracker'!$F$4:$F$93,$A8,'Daily Order Tracker'!$R$4:$R$93,14) -> 2 | Q8: =COUNTIFS('Daily Order Tracker'!$F$4:$F$93,$A8,'Daily Order Tracker'!$R$4:$R$93,15) -> 1 | R8: =COUNTIFS('Daily Order Tracker'!$F$4:$F$93,$A8,'Daily Order Tracker'!$R$4:$R$93,16) -> 0 | S8: =COUNTIFS('Daily Order Tracker'!$F$4:$F$93,$A8,'Daily Order Tracker'!$R$4:$R$93,17) -> 2 | T8: =COUNTIFS('Daily Order Tracker'!$F$4:$F$93,$A8,'Daily Order Tracker'!$R$4:$R$93,18) -> 1 | U8: =COUNTIFS('Daily Order Tracker'!$F$4:$F$93,$A8,'Daily Order Tracker'!$R$4:$R$93,19) -> 0 | V8: =COUNTIFS('Daily Order Tracker'!$F$4:$F$93,$A8,'Daily Order Tracker'!$R$4:$R$93,20) -> 0 | W8: =COUNTIFS('Daily Order Tracker'!$F$4:$F$93,$A8,'Daily Order Tracker'!$R$4:$R$93,21) -> 1 | X8: =COUNTIFS('Daily Order Tracker'!$F$4:$F$93,$A8,'Daily Order Tracker'!$R$4:$R$93,22) -> 0 | Y8: =COUNTIFS('Daily Order Tracker'!$F$4:$F$93,$A8,'Daily Order Tracker'!$R$4:$R$93,23) -> 0 | Z8: =MAX(B8:Y8) -> 2 | AA8: =SUM(B8:E8) -> 0 | AB8: =SUM(F8:I8) -> 0 | AC8: =SUM(J8:M8) -> 1 | AD8: =SUM(N8:Q8) -> 4 | AE8: =SUM(R8:U8) -> 3 | AF8: =SUM(V8:Y8) -> 1
A9: Swish Kitchen - BTM Layout | B9: =COUNTIFS('Daily Order Tracker'!$F$4:$F$93,$A9,'Daily Order Tracker'!$R$4:$R$93,0) -> 0 | C9: =COUNTIFS('Daily Order Tracker'!$F$4:$F$93,$A9,'Daily Order Tracker'!$R$4:$R$93,1) -> 0 | D9: =COUNTIFS('Daily Order Tracker'!$F$4:$F$93,$A9,'Daily Order Tracker'!$R$4:$R$93,2) -> 0 | E9: =COUNTIFS('Daily Order Tracker'!$F$4:$F$93,$A9,'Daily Order Tracker'!$R$4:$R$93,3) -> 0 | F9: =COUNTIFS('Daily Order Tracker'!$F$4:$F$93,$A9,'Daily Order Tracker'!$R$4:$R$93,4) -> 0 | G9: =COUNTIFS('Daily Order Tracker'!$F$4:$F$93,$A9,'Daily Order Tracker'!$R$4:$R$93,5) -> 0 | H9: =COUNTIFS('Daily Order Tracker'!$F$4:$F$93,$A9,'Daily Order Tracker'!$R$4:$R$93,6) -> 0 | I9: =COUNTIFS('Daily Order Tracker'!$F$4:$F$93,$A9,'Daily Order Tracker'!$R$4:$R$93,7) -> 0 | J9: =COUNTIFS('Daily Order Tracker'!$F$4:$F$93,$A9,'Daily Order Tracker'!$R$4:$R$93,8) -> 0 | K9: =COUNTIFS('Daily Order Tracker'!$F$4:$F$93,$A9,'Daily Order Tracker'!$R$4:$R$93,9) -> 0 | L9: =COUNTIFS('Daily Order Tracker'!$F$4:$F$93,$A9,'Daily Order Tracker'!$R$4:$R$93,10) -> 1 | M9: =COUNTIFS('Daily Order Tracker'!$F$4:$F$93,$A9,'Daily Order Tracker'!$R$4:$R$93,11) -> 2 | N9: =COUNTIFS('Daily Order Tracker'!$F$4:$F$93,$A9,'Daily Order Tracker'!$R$4:$R$93,12) -> 0 | O9: =COUNTIFS('Daily Order Tracker'!$F$4:$F$93,$A9,'Daily Order Tracker'!$R$4:$R$93,13) -> 0 | P9: =COUNTIFS('Daily Order Tracker'!$F$4:$F$93,$A9,'Daily Order Tracker'!$R$4:$R$93,14) -> 1 | Q9: =COUNTIFS('Daily Order Tracker'!$F$4:$F$93,$A9,'Daily Order Tracker'!$R$4:$R$93,15) -> 0 | R9: =COUNTIFS('Daily Order Tracker'!$F$4:$F$93,$A9,'Daily Order Tracker'!$R$4:$R$93,16) -> 0 | S9: =COUNTIFS('Daily Order Tracker'!$F$4:$F$93,$A9,'Daily Order Tracker'!$R$4:$R$93,17) -> 1 | T9: =COUNTIFS('Daily Order Tracker'!$F$4:$F$93,$A9,'Daily Order Tracker'!$R$4:$R$93,18) -> 0 | U9: =COUNTIFS('Daily Order Tracker'!$F$4:$F$93,$A9,'Daily Order Tracker'!$R$4:$R$93,19) -> 1 | V9: =COUNTIFS('Daily Order Tracker'!$F$4:$F$93,$A9,'Daily Order Tracker'!$R$4:$R$93,20) -> 2 | W9: =COUNTIFS('Daily Order Tracker'!$F$4:$F$93,$A9,'Daily Order Tracker'!$R$4:$R$93,21) -> 1 | X9: =COUNTIFS('Daily Order Tracker'!$F$4:$F$93,$A9,'Daily Order Tracker'!$R$4:$R$93,22) -> 0 | Y9: =COUNTIFS('Daily Order Tracker'!$F$4:$F$93,$A9,'Daily Order Tracker'!$R$4:$R$93,23) -> 0 | Z9: =MAX(B9:Y9) -> 2 | AA9: =SUM(B9:E9) -> 0 | AB9: =SUM(F9:I9) -> 0 | AC9: =SUM(J9:M9) -> 3 | AD9: =SUM(N9:Q9) -> 1 | AE9: =SUM(R9:U9) -> 2 | AF9: =SUM(V9:Y9) -> 3
A10: Swish Kitchen - Bellandur | B10: =COUNTIFS('Daily Order Tracker'!$F$4:$F$93,$A10,'Daily Order Tracker'!$R$4:$R$93,0) -> 0 | C10: =COUNTIFS('Daily Order Tracker'!$F$4:$F$93,$A10,'Daily Order Tracker'!$R$4:$R$93,1) -> 0 | D10: =COUNTIFS('Daily Order Tracker'!$F$4:$F$93,$A10,'Daily Order Tracker'!$R$4:$R$93,2) -> 0 | E10: =COUNTIFS('Daily Order Tracker'!$F$4:$F$93,$A10,'Daily Order Tracker'!$R$4:$R$93,3) -> 0 | F10: =COUNTIFS('Daily Order Tracker'!$F$4:$F$93,$A10,'Daily Order Tracker'!$R$4:$R$93,4) -> 0 | G10: =COUNTIFS('Daily Order Tracker'!$F$4:$F$93,$A10,'Daily Order Tracker'!$R$4:$R$93,5) -> 0 | H10: =COUNTIFS('Daily Order Tracker'!$F$4:$F$93,$A10,'Daily Order Tracker'!$R$4:$R$93,6) -> 0 | I10: =COUNTIFS('Daily Order Tracker'!$F$4:$F$93,$A10,'Daily Order Tracker'!$R$4:$R$93,7) -> 0 | J10: =COUNTIFS('Daily Order Tracker'!$F$4:$F$93,$A10,'Daily Order Tracker'!$R$4:$R$93,8) -> 0 | K10: =COUNTIFS('Daily Order Tracker'!$F$4:$F$93,$A10,'Daily Order Tracker'!$R$4:$R$93,9) -> 0 | L10: =COUNTIFS('Daily Order Tracker'!$F$4:$F$93,$A10,'Daily Order Tracker'!$R$4:$R$93,10) -> 1 | M10: =COUNTIFS('Daily Order Tracker'!$F$4:$F$93,$A10,'Daily Order Tracker'!$R$4:$R$93,11) -> 1 | N10: =COUNTIFS('Daily Order Tracker'!$F$4:$F$93,$A10,'Daily Order Tracker'!$R$4:$R$93,12) -> 0 | O10: =COUNTIFS('Daily Order Tracker'!$F$4:$F$93,$A10,'Daily Order Tracker'!$R$4:$R$93,13) -> 1 | P10: =COUNTIFS('Daily Order Tracker'!$F$4:$F$93,$A10,'Daily Order Tracker'!$R$4:$R$93,14) -> 0 | Q10: =COUNTIFS('Daily Order Tracker'!$F$4:$F$93,$A10,'Daily Order Tracker'!$R$4:$R$93,15) -> 0 | R10: =COUNTIFS('Daily Order Tracker'!$F$4:$F$93,$A10,'Daily Order Tracker'!$R$4:$R$93,16) -> 2 | S10: =COUNTIFS('Daily Order Tracker'!$F$4:$F$93,$A10,'Daily Order Tracker'!$R$4:$R$93,17) -> 1 | T10: =COUNTIFS('Daily Order Tracker'!$F$4:$F$93,$A10,'Daily Order Tracker'!$R$4:$R$93,18) -> 2 | U10: =COUNTIFS('Daily Order Tracker'!$F$4:$F$93,$A10,'Daily Order Tracker'!$R$4:$R$93,19) -> 0 | V10: =COUNTIFS('Daily Order Tracker'!$F$4:$F$93,$A10,'Daily Order Tracker'!$R$4:$R$93,20) -> 0 | W10: =COUNTIFS('Daily Order Tracker'!$F$4:$F$93,$A10,'Daily Order Tracker'!$R$4:$R$93,21) -> 1 | X10: =COUNTIFS('Daily Order Tracker'!$F$4:$F$93,$A10,'Daily Order Tracker'!$R$4:$R$93,22) -> 0 | Y10: =COUNTIFS('Daily Order Tracker'!$F$4:$F$93,$A10,'Daily Order Tracker'!$R$4:$R$93,23) -> 0 | Z10: =MAX(B10:Y10) -> 2 | AA10: =SUM(B10:E10) -> 0 | AB10: =SUM(F10:I10) -> 0 | AC10: =SUM(J10:M10) -> 2 | AD10: =SUM(N10:Q10) -> 1 | AE10: =SUM(R10:U10) -> 5 | AF10: =SUM(V10:Y10) -> 1
A11: Swish Kitchen - Sarjapur | B11: =COUNTIFS('Daily Order Tracker'!$F$4:$F$93,$A11,'Daily Order Tracker'!$R$4:$R$93,0) -> 0 | C11: =COUNTIFS('Daily Order Tracker'!$F$4:$F$93,$A11,'Daily Order Tracker'!$R$4:$R$93,1) -> 0 | D11: =COUNTIFS('Daily Order Tracker'!$F$4:$F$93,$A11,'Daily Order Tracker'!$R$4:$R$93,2) -> 0 | E11: =COUNTIFS('Daily Order Tracker'!$F$4:$F$93,$A11,'Daily Order Tracker'!$R$4:$R$93,3) -> 0 | F11: =COUNTIFS('Daily Order Tracker'!$F$4:$F$93,$A11,'Daily Order Tracker'!$R$4:$R$93,4) -> 0 | G11: =COUNTIFS('Daily Order Tracker'!$F$4:$F$93,$A11,'Daily Order Tracker'!$R$4:$R$93,5) -> 0 | H11: =COUNTIFS('Daily Order Tracker'!$F$4:$F$93,$A11,'Daily Order Tracker'!$R$4:$R$93,6) -> 0 | I11: =COUNTIFS('Daily Order Tracker'!$F$4:$F$93,$A11,'Daily Order Tracker'!$R$4:$R$93,7) -> 0 | J11: =COUNTIFS('Daily Order Tracker'!$F$4:$F$93,$A11,'Daily Order Tracker'!$R$4:$R$93,8) -> 0 | K11: =COUNTIFS('Daily Order Tracker'!$F$4:$F$93,$A11,'Daily Order Tracker'!$R$4:$R$93,9) -> 0 | L11: =COUNTIFS('Daily Order Tracker'!$F$4:$F$93,$A11,'Daily Order Tracker'!$R$4:$R$93,10) -> 2 | M11: =COUNTIFS('Daily Order Tracker'!$F$4:$F$93,$A11,'Daily Order Tracker'!$R$4:$R$93,11) -> 0 | N11: =COUNTIFS('Daily Order Tracker'!$F$4:$F$93,$A11,'Daily Order Tracker'!$R$4:$R$93,12) -> 2 | O11: =COUNTIFS('Daily Order Tracker'!$F$4:$F$93,$A11,'Daily Order Tracker'!$R$4:$R$93,13) -> 0 | P11: =COUNTIFS('Daily Order Tracker'!$F$4:$F$93,$A11,'Daily Order Tracker'!$R$4:$R$93,14) -> 0 | Q11: =COUNTIFS('Daily Order Tracker'!$F$4:$F$93,$A11,'Daily Order Tracker'!$R$4:$R$93,15) -> 0 | R11: =COUNTIFS('Daily Order Tracker'!$F$4:$F$93,$A11,'Daily Order Tracker'!$R$4:$R$93,16) -> 2 | S11: =COUNTIFS('Daily Order Tracker'!$F$4:$F$93,$A11,'Daily Order Tracker'!$R$4:$R$93,17) -> 0 | T11: =COUNTIFS('Daily Order Tracker'!$F$4:$F$93,$A11,'Daily Order Tracker'!$R$4:$R$93,18) -> 0 | U11: =COUNTIFS('Daily Order Tracker'!$F$4:$F$93,$A11,'Daily Order Tracker'!$R$4:$R$93,19) -> 1 | V11: =COUNTIFS('Daily Order Tracker'!$F$4:$F$93,$A11,'Daily Order Tracker'!$R$4:$R$93,20) -> 0 | W11: =COUNTIFS('Daily Order Tracker'!$F$4:$F$93,$A11,'Daily Order Tracker'!$R$4:$R$93,21) -> 2 | X11: =COUNTIFS('Daily Order Tracker'!$F$4:$F$93,$A11,'Daily Order Tracker'!$R$4:$R$93,22) -> 0 | Y11: =COUNTIFS('Daily Order Tracker'!$F$4:$F$93,$A11,'Daily Order Tracker'!$R$4:$R$93,23) -> 0 | Z11: =MAX(B11:Y11) -> 2 | AA11: =SUM(B11:E11) -> 0 | AB11: =SUM(F11:I11) -> 0 | AC11: =SUM(J11:M11) -> 2 | AD11: =SUM(N11:Q11) -> 2 | AE11: =SUM(R11:U11) -> 3 | AF11: =SUM(V11:Y11) -> 2
A12: TOTAL | B12: =SUM(B2:B11) -> 0 | C12: =SUM(C2:C11) -> 0 | D12: =SUM(D2:D11) -> 0 | E12: =SUM(E2:E11) -> 0 | F12: =SUM(F2:F11) -> 0 | G12: =SUM(G2:G11) -> 0 | H12: =SUM(H2:H11) -> 0 | I12: =SUM(I2:I11) -> 0 | ... Y12: =SUM(Y2:Y11) -> 0

Sheet Kitchen Operations Tracker
A1: KITCHEN OPERATIONS TRACKER
A2: Auto-calculated from Daily Order Tracker.
A3: Kitchen Name | B3: Zone | C3: Shift | D3: Chef | E3: Orders Received | F3: Orders Preparing | G3: Orders Ready | H3: Average Prep Time (min) | I3: Delayed Orders | J3: Peak Hour Load | K3: Efficiency %
A4: Swish Kitchen - Koramangala | B4: Koramangala | C4: Morning (7AM-3PM) | D4: Ravi Kumar | E4: =COUNTIF('Daily Order Tracker'!$F$4:$F$93,A4) -> 9 | F4: =COUNTIFS('Daily Order Tracker'!$F$4:$F$93,A4,'Daily Order Tracker'!$N$4:$N$93,"Preparing") -> 1 | G4: =COUNTIFS('Daily Order Tracker'!$F$4:$F$93,A4,'Daily Order Tracker'!$N$4:$N$93,"Ready") -> 0 | H4: =IFERROR(AVERAGEIFS('Daily Order Tracker'!$Q$4:$Q$93,'Daily Order Tracker'!$F$4:$F$93,A4,'Daily Order Tracker'!$Q$4:$Q$93,"<>"),0) -> 4.875 | I4: =COUNTIFS('Daily Order Tracker'!$F$4:$F$93,A4,'Daily Order Tracker'!$S$4:$S$93,"Y") -> 4 | J4: =INDEX(Hourly_Helper!$Z$2:$Z$11,MATCH(A4,Hourly_Helper!$A$2:$A$11,0)) -> 2 | K4: =IFERROR((E4-I4)/E4,0) -> 0.55555556
A5: Swish Kitchen - HSR Layout | B5: HSR Layout | C5: Afternoon (11AM-7PM) | D5: Ananya Rao | E5: =COUNTIF('Daily Order Tracker'!$F$4:$F$93,A5) -> 9 | F5: =COUNTIFS('Daily Order Tracker'!$F$4:$F$93,A5,'Daily Order Tracker'!$N$4:$N$93,"Preparing") -> 0 | G5: =COUNTIFS('Daily Order Tracker'!$F$4:$F$93,A5,'Daily Order Tracker'!$N$4:$N$93,"Ready") -> 0 | H5: =IFERROR(AVERAGEIFS('Daily Order Tracker'!$Q$4:$Q$93,'Daily Order Tracker'!$F$4:$F$93,A5,'Daily Order Tracker'!$Q$4:$Q$93,"<>"),0) -> 6.5 | I5: =COUNTIFS('Daily Order Tracker'!$F$4:$F$93,A5,'Daily Order Tracker'!$S$4:$S$93,"Y") -> 5 | J5: =INDEX(Hourly_Helper!$Z$2:$Z$11,MATCH(A5,Hourly_Helper!$A$2:$A$11,0)) -> 2 | K5: =IFERROR((E5-I5)/E5,0) -> 0.44444444
A6: Swish Kitchen - Indiranagar | B6: Indiranagar | C6: Evening (3PM-11PM) | D6: Suresh Iyer | E6: =COUNTIF('Daily Order Tracker'!$F$4:$F$93,A6) -> 9 | F6: =COUNTIFS('Daily Order Tracker'!$F$4:$F$93,A6,'Daily Order Tracker'!$N$4:$N$93,"Preparing") -> 0 | G6: =COUNTIFS('Daily Order Tracker'!$F$4:$F$93,A6,'Daily Order Tracker'!$N$4:$N$93,"Ready") -> 0 | H6: =IFERROR(AVERAGEIFS('Daily Order Tracker'!$Q$4:$Q$93,'Daily Order Tracker'!$F$4:$F$93,A6,'Daily Order Tracker'!$Q$4:$Q$93,"<>"),0) -> 5.7142857 | I6: =COUNTIFS('Daily Order Tracker'!$F$4:$F$93,A6,'Daily Order Tracker'!$S$4:$S$93,"Y") -> 6 | J6: =INDEX(Hourly_Helper!$Z$2:$Z$11,MATCH(A6,Hourly_Helper!$A$2:$A$11,0)) -> 3 | K6: =IFERROR((E6-I6)/E6,0) -> 0.33333333
A7: Swish Kitchen - Whitefield | B7: Whitefield | C7: Night (6PM-2AM) | D7: Fatima Sheikh | E7: =COUNTIF('Daily Order Tracker'!$F$4:$F$93,A7) -> 9 | F7: =COUNTIFS('Daily Order Tracker'!$F$4:$F$93,A7,'Daily Order Tracker'!$N$4:$N$93,"Preparing") -> 0 | G7: =COUNTIFS('Daily Order Tracker'!$F$4:$F$93,A7,'Daily Order Tracker'!$N$4:$N$93,"Ready") -> 0 | H7: =IFERROR(AVERAGEIFS('Daily Order Tracker'!$Q$4:$Q$93,'Daily Order Tracker'!$F$4:$F$93,A7,'Daily Order Tracker'!$Q$4:$Q$93,"<>"),0) -> 6.2857143 | I7: =COUNTIFS('Daily Order Tracker'!$F$4:$F$93,A7,'Daily Order Tracker'!$S$4:$S$93,"Y") -> 5 | J7: =INDEX(Hourly_Helper!$Z$2:$Z$11,MATCH(A7,Hourly_Helper!$A$2:$A$11,0)) -> 2 | K7: =IFERROR((E7-I7)/E7,0) -> 0.44444444
A8: Swish Kitchen - Electronic City | B8: Electronic City | C8: Morning (7AM-3PM) | D8: Vikram Singh | E8: =COUNTIF('Daily Order Tracker'!$F$4:$F$93,A8) -> 9 | F8: =COUNTIFS('Daily Order Tracker'!$F$4:$F$93,A8,'Daily Order Tracker'!$N$4:$N$93,"Preparing") -> 0 | G8: =COUNTIFS('Daily Order Tracker'!$F$4:$F$93,A8,'Daily Order Tracker'!$N$4:$N$93,"Ready") -> 0 | H8: =IFERROR(AVERAGEIFS('Daily Order Tracker'!$Q$4:$Q$93,'Daily Order Tracker'!$F$4:$F$93,A8,'Daily Order Tracker'!$Q$4:$Q$93,"<>"),0) -> 6.75 | I8: =COUNTIFS('Daily Order Tracker'!$F$4:$F$93,A8,'Daily Order Tracker'!$S$4:$S$93,"Y") -> 8 | J8: =INDEX(Hourly_Helper!$Z$2:$Z$11,MATCH(A8,Hourly_Helper!$A$2:$A$11,0)) -> 2 | K8: =IFERROR((E8-I8)/E8,0) -> 0.11111111
A9: Swish Kitchen - Marathahalli | B9: Marathahalli | C9: Afternoon (11AM-7PM) | D9: Deepa Nair | E9: =COUNTIF('Daily Order Tracker'!$F$4:$F$93,A9) -> 9 | F9: =COUNTIFS('Daily Order Tracker'!$F$4:$F$93,A9,'Daily Order Tracker'!$N$4:$N$93,"Preparing") -> 0 | G9: =COUNTIFS('Daily Order Tracker'!$F$4:$F$93,A9,'Daily Order Tracker'!$N$4:$N$93,"Ready") -> 1 | H9: =IFERROR(AVERAGEIFS('Daily Order Tracker'!$Q$4:$Q$93,'Daily Order Tracker'!$F$4:$F$93,A9,'Daily Order Tracker'!$Q$4:$Q$93,"<>"),0) -> 5.3333333 | I9: =COUNTIFS('Daily Order Tracker'!$F$4:$F$93,A9,'Daily Order Tracker'!$S$4:$S$93,"Y") -> 3 | J9: =INDEX(Hourly_Helper!$Z$2:$Z$11,MATCH(A9,Hourly_Helper!$A$2:$A$11,0)) -> 3 | K9: =IFERROR((E9-I9)/E9,0) -> 0.66666667
A10: Swish Kitchen - JP Nagar | B10: JP Nagar | C10: Evening (3PM-11PM) | D10: Arjun Reddy | E10: =COUNTIF('Daily Order Tracker'!$F$4:$F$93,A10) -> 9 | F10: =COUNTIFS('Daily Order Tracker'!$F$4:$F$93,A10,'Daily Order Tracker'!$N$4:$N$93,"Preparing") -> 1 | G10: =COUNTIFS('Daily Order Tracker'!$F$4:$F$93,A10,'Daily Order Tracker'!$N$4:$N$93,"Ready") -> 0 | H10: =IFERROR(AVERAGEIFS('Daily Order Tracker'!$Q$4:$Q$93,'Daily Order Tracker'!$F$4:$F$93,A10,'Daily Order Tracker'!$Q$4:$Q$93,"<>"),0) -> 6.5714286 | I10: =COUNTIFS('Daily Order Tracker'!$F$4:$F$93,A10,'Daily Order Tracker'!$S$4:$S$93,"Y") -> 6 | J10: =INDEX(Hourly_Helper!$Z$2:$Z$11,MATCH(A10,Hourly_Helper!$A$2:$A$11,0)) -> 2 | K10: =IFERROR((E10-I10)/E10,0) -> 0.33333333
A11: Swish Kitchen - BTM Layout | B11: BTM Layout | C11: Night (6PM-2AM) | D11: Meera Pillai | E11: =COUNTIF('Daily Order Tracker'!$F$4:$F$93,A11) -> 9 | F11: =COUNTIFS('Daily Order Tracker'!$F$4:$F$93,A11,'Daily Order Tracker'!$N$4:$N$93,"Preparing") -> 1 | G11: =COUNTIFS('Daily Order Tracker'!$F$4:$F$93,A11,'Daily Order Tracker'!$N$4:$N$93,"Ready") -> 0 | H11: =IFERROR(AVERAGEIFS('Daily Order Tracker'!$Q$4:$Q$93,'Daily Order Tracker'!$F$4:$F$93,A11,'Daily Order Tracker'!$Q$4:$Q$93,"<>"),0) -> 5.875 | I11: =COUNTIFS('Daily Order Tracker'!$F$4:$F$93,A11,'Daily Order Tracker'!$S$4:$S$93,"Y") -> 6 | J11: =INDEX(Hourly_Helper!$Z$2:$Z$11,MATCH(A11,Hourly_Helper!$A$2:$A$11,0)) -> 2 | K11: =IFERROR((E11-I11)/E11,0) -> 0.33333333
A12: Swish Kitchen - Bellandur | B12: Bellandur | C12: Morning (7AM-3PM) | D12: Naveen Gowda | E12: =COUNTIF('Daily Order Tracker'!$F$4:$F$93,A12) -> 9 | F12: =COUNTIFS('Daily Order Tracker'!$F$4:$F$93,A12,'Daily Order Tracker'!$N$4:$N$93,"Preparing") -> 0 | G12: =COUNTIFS('Daily Order Tracker'!$F$4:$F$93,A12,'Daily Order Tracker'!$N$4:$N$93,"Ready") -> 0 | H12: =IFERROR(AVERAGEIFS('Daily Order Tracker'!$Q$4:$Q$93,'Daily Order Tracker'!$F$4:$F$93,A12,'Daily Order Tracker'!$Q$4:$Q$93,"<>"),0) -> 6 | I12: =COUNTIFS('Daily Order Tracker'!$F$4:$F$93,A12,'Daily Order Tracker'!$S$4:$S$93,"Y") -> 6 | J12: =INDEX(Hourly_Helper!$Z$2:$Z$11,MATCH(A12,Hourly_Helper!$A$2:$A$11,0)) -> 2 | K12: =IFERROR((E12-I12)/E12,0) -> 0.33333333
A13: Swish Kitchen - Sarjapur | B13: Sarjapur | C13: Afternoon (11AM-7PM) | D13: Priya Menon | E13: =COUNTIF('Daily Order Tracker'!$F$4:$F$93,A13) -> 9 | F13: =COUNTIFS('Daily Order Tracker'!$F$4:$F$93,A13,'Daily Order Tracker'!$N$4:$N$93,"Preparing") -> 0 | G13: =COUNTIFS('Daily Order Tracker'!$F$4:$F$93,A13,'Daily Order Tracker'!$N$4:$N$93,"Ready") -> 0 | H13: =IFERROR(AVERAGEIFS('Daily Order Tracker'!$Q$4:$Q$93,'Daily Order Tracker'!$F$4:$F$93,A13,'Daily Order Tracker'!$Q$4:$Q$93,"<>"),0) -> 5.5714286 | I13: =COUNTIFS('Daily Order Tracker'!$F$4:$F$93,A13,'Daily Order Tracker'!$S$4:$S$93,"Y") -> 5 | J13: =INDEX(Hourly_Helper!$Z$2:$Z$11,MATCH(A13,Hourly_Helper!$A$2:$A$11,0)) -> 2 | K13: =IFERROR((E13-I13)/E13,0) -> 0.44444444

Sheet Food Preparation Monitor
A1: FOOD PREPARATION MONITOR
A2: Sample batch snapshot — Prep Time and Delay Flag are live formulas.
A3: Item Name | B3: Category | C3: Order Quantity | D3: Prep Start | E3: Prep End | F3: Prep Time (min) | G3: Target Time (min) | H3: Delay Flag
A4: Veg Fried Rice | B4: Rice Bowls | C4: 58 | D4: 0.81805556 | E4: 0.82361111 | F4: =(E4-D4)*1440 -> 8 | G4: 6 | H4: =IF(F4>G4,"DELAYED","On Time") -> DELAYED
A5: Chicken Noodles | B5: Noodles | C5: 23 | D5: 0.5875 | E5: 0.59652778 | F5: =(E5-D5)*1440 -> 13 | G5: 10 | H5: =IF(F5>G5,"DELAYED","On Time") -> DELAYED
A6: Paneer Wrap | B6: Snacks | C6: 51 | D6: 0.57361111 | E6: 0.58611111 | F6: =(E6-D6)*1440 -> 18 | G6: 12 | H6: =IF(F6>G6,"DELAYED","On Time") -> DELAYED
A7: Cold Coffee | B7: Beverages | C7: 34 | D7: 0.58680556 | E7: 0.59305556 | F7: =(E7-D7)*1440 -> 9 | G7: 10 | H7: =IF(F7>G7,"DELAYED","On Time") -> On Time
A8: Gulab Jamun | B8: Sweets | C8: 59 | D8: 0.57013889 | E8: 0.58055556 | F8: =(E8-D8)*1440 -> 15 | G8: 12 | H8: =IF(F8>G8,"DELAYED","On Time") -> DELAYED
A9: Masala Dosa Roll | B9: Wraps | C9: 31 | D9: 0.78125 | E9: 0.78611111 | F9: =(E9-D9)*1440 -> 7 | G9: 6 | H9: =IF(F9>G9,"DELAYED","On Time") -> DELAYED
A10: Chicken Momos | B10: Rice Bowls | C10: 63 | D10: 0.82638889 | E10: 0.83125 | F10: =(E10-D10)*1440 -> 7 | G10: 8 | H10: =IF(F10>G10,"DELAYED","On Time") -> On Time
A11: Veg Momos | B11: Noodles | C11: 26 | D11: 0.82083333 | E11: 0.83055556 | F11: =(E11-D11)*1440 -> 14 | G11: 9 | H11: =IF(F11>G11,"DELAYED","On Time") -> DELAYED
A12: Mango Lassi | B12: Snacks | C12: 61 | D12: 0.39097222 | E12: 0.39583333 | F12: =(E12-D12)*1440 -> 7 | G12: 8 | H12: =IF(F12>G12,"DELAYED","On Time") -> On Time
A13: Butter Naan Wrap | B13: Beverages | C13: 42 | D13: 0.61736111 | E13: 0.62361111 | F13: =(E13-D13)*1440 -> 9 | G13: 9 | H13: =IF(F13>G13,"DELAYED","On Time") -> On Time
A14: Egg Fried Rice | B14: Sweets | C14: 43 | D14: 0.46458333 | E14: 0.46944444 | F14: =(E14-D14)*1440 -> 7 | G14: 6 | H14: =IF(F14>G14,"DELAYED","On Time") -> DELAYED
A15: Chocolate Shake | B15: Wraps | C15: 27 | D15: 0.74236111 | E15: 0.75277778 | F15: =(E15-D15)*1440 -> 15 | G15: 10 | H15: =IF(F15>G15,"DELAYED","On Time") -> DELAYED
... A23: Schezwan Noodles | B23: Noodles | C23: 51 | D23: 0.64722222 | E23: 0.65625 | F23: =(E23-D23)*1440 -> 13 | G23: 10 | H23: =IF(F23>G23,"DELAYED","On Time") -> DELAYED

Sheet Rider Performance Tracker
A1: RIDER PERFORMANCE TRACKER
A2: Assumptions box (right) drives Earnings — edit the blue input cell to re-price all riders.
A3: Rider ID | B3: Rider Name | C3: Zone | D3: Shift | E3: Orders Assigned | F3: Orders Delivered | G3: Average Delivery Time (min) | H3: Distance Covered (km) | I3: Online Hours | J3: Idle Time (hrs) | K3: Earnings (₹) | L3: Incentives (₹) | M3: Acceptance Rate | O3: ASSUMPTIONS
